Traceback (most recent call last):
  File "/usr/local/lib/python3.6/site-packages/vcd_cli/vm.py", line 362, in list_vms
    raise Exception('not implemented')
Exception: not implemented

Traceback (most recent call last):
  File "/usr/local/lib/python3.6/site-packages/vcd_cli/vm.py", line 362, in list_vms
    raise Exception('not implemented')
Exception: not implemented

Traceback (most recent call last):
  File "/usr/lib/python3.6/site-packages/urllib3/connection.py", line 162, in _new_conn
    (self._dns_host, self.port), self.timeout, **extra_kw)
  File "/usr/lib/python3.6/site-packages/urllib3/util/connection.py", line 57, in create_connection
    for res in socket.getaddrinfo(host, port, family, socket.SOCK_STREAM):
  File "/usr/lib64/python3.6/socket.py", line 745, in getaddrinfo
    for res in _socket.getaddrinfo(host, port, family, type, proto, flags):
socket.gaierror: [Errno -2] Name or service not known

During handling of the above exception, another exception occurred:

Traceback (most recent call last):
  File "/usr/lib/python3.6/site-packages/urllib3/connectionpool.py", line 600, in urlopen
    chunked=chunked)
  File "/usr/lib/python3.6/site-packages/urllib3/connectionpool.py", line 343, in _make_request
    self._validate_conn(conn)
  File "/usr/lib/python3.6/site-packages/urllib3/connectionpool.py", line 839, in _validate_conn
    conn.connect()
  File "/usr/lib/python3.6/site-packages/urllib3/connection.py", line 315, in connect
    conn = self._new_conn()
  File "/usr/lib/python3.6/site-packages/urllib3/connection.py", line 171, in _new_conn
    self, "Failed to establish a new connection: %s" % e)
urllib3.exceptions.NewConnectionError: <urllib3.connection.VerifiedHTTPSConnection object at 0x7f521ce72320>: Failed to establish a new connection: [Errno -2] Name or service not known

During handling of the above exception, another exception occurred:

Traceback (most recent call last):
  File "/usr/lib/python3.6/site-packages/requests/adapters.py", line 449, in send
    timeout=timeout
  File "/usr/lib/python3.6/site-packages/urllib3/connectionpool.py", line 638, in urlopen
    _stacktrace=sys.exc_info()[2])
  File "/usr/lib/python3.6/site-packages/urllib3/util/retry.py", line 399, in increment
    raise MaxRetryError(_pool, url, error or ResponseError(cause))
urllib3.exceptions.MaxRetryError: HTTPSConnectionPool(host='fradir01.vmware-solutions.cloud.ibm.com', port=443): Max retries exceeded with url: /api/session (Caused by NewConnectionError('<urllib3.connection.VerifiedHTTPSConnection object at 0x7f521ce72320>: Failed to establish a new connection: [Errno -2] Name or service not known',))

During handling of the above exception, another exception occurred:

Traceback (most recent call last):
  File "/usr/local/lib/python3.6/site-packages/vcd_cli/vm.py", line 391, in info
    restore_session(ctx, vdc_required=True)
  File "/usr/local/lib/python3.6/site-packages/vcd_cli/utils.py", line 125, in restore_session
    profiles.get('token'), profiles.get('is_jwt_token'))
  File "/usr/local/lib/python3.6/site-packages/pyvcloud/vcd/client.py", line 1042, in rehydrate_from_token
    new_session)
  File "/usr/local/lib/python3.6/site-packages/pyvcloud/vcd/client.py", line 1311, in _do_request_prim
    verify=self._verify_ssl_certs)
  File "/usr/lib/python3.6/site-packages/requests/sessions.py", line 533, in request
    resp = self.send(prep, **send_kwargs)
  File "/usr/lib/python3.6/site-packages/requests/sessions.py", line 646, in send
    r = adapter.send(request, **kwargs)
  File "/usr/lib/python3.6/site-packages/requests/adapters.py", line 516, in send
    raise ConnectionError(e, request=request)
requests.exceptions.ConnectionError: HTTPSConnectionPool(host='fradir01.vmware-solutions.cloud.ibm.com', port=443): Max retries exceeded with url: /api/session (Caused by NewConnectionError('<urllib3.connection.VerifiedHTTPSConnection object at 0x7f521ce72320>: Failed to establish a new connection: [Errno -2] Name or service not known',))

